Workbook

Sheet DOMO
A1: ID | B1: Origem | C1: Tipologia | D1: Area | E1: Data_Manifestacao | F1: Agente | G1: Status_Solicitação | H1: Status_Acao | I1: Cliente | J1: UC | K1: Obra_Const_Man | L1: Regional | M1: Localidade | N1: Poder | O1: Prefeitura | P1: Manifestação | Q1: Data_Envio_Area | R1: Descricao_da_acao | S1: Data_Resp_Area | T1: Resposta_Area | U1: Expectativa_Cliente | V1: Data_Prev_Acao | W1: Data_Conclusao | X1: Resp_Tratativa | Y1: Registrado_por | Z1: Participantes_Municipio | AA1: Participantes_Energisa_txt | AB1: Critico | AC1: Acao | AD1: Modificado | AE1: Modificado por.title | AF1: Criado | AG1: Criado por.title | AH1: Peso_I_INST | AI1: Peso_I_INST_2 | AJ1: Peso_Geral | AK1: Processo | AL1: Previsao | AM1: Sub_Areas | AN1: Supervisão | AO1: dias das soliictações | AP1: aging | AQ1: Expectativa | AR1: Risco | AS1: Integrar | AT1: SLA | AU1: Area 2
A2: 1008 | B2: Visita Domo de Ferro | C2: Obra | D2: DCMD | E2: 46246 | F2: Monike Chaves | G2: Em Andamento | H2: Em Andamento | K2: 0402600304 | L2: SUL | M2: Coronel Sapucaia | N2: Prefeitura | O2: Coronel Sapucaia | P2: Obra parada precisa remover a estrutura para seguir com a parte interna, prefeitura quer intervir na rede, foi orientando quanto ao risco a segurança, e continuidade do fornecimento. Escola será entregue no dia 02/09/2026 e precisamos que a obra seja atendida antes dessa data. | Q2: 46265 | R2: 0402600304 PROGRAMAR OBRA | S2: 46280 | T2: Reprogramada para 18/09 - devido a contingência | U2: 46273 | V2: 46283 | X2: Amanda Aparecida Teixeira dos Santos | Y2: Amanda Santos | Z2: Thiago Secretario De Administração Prefeitura De Cel Sapucaia | AB2: Sim | AC2: Visita Domo de Ferro | AD2: 46280 | AE2: Amanda Aparecida Teixeira dos Santos | AF2: 46280 | AG2: Amanda Aparecida Teixeira dos Santos | AH2: 100 | AI2: 100 | AJ2: 100 | AN2: =VLOOKUP(M2,[1]municipios!$B:$D,3,0) -> PONTA PORA | AO2: =TODAY()-E2 -> 42 | AP2: =IF(AO2<=5,"0–5 dias",IF(AO2<=15,"6–15 dias",IF(AO2<=16,"16–30 dias",IF(AO2<=30,"30–50 dias",">50 dias")))) -> >50 dias | AQ2: =IF(U2="","Dentro",(IF(IF(W2="",TODAY(),W2)<=U2,"Dentro","Fora"))) -> Fora | AR2: =IF(U2="","Não risco",IF((TODAY()-U2)<=7,"Risco","Não risco")) -> Não risco | AS2: =IF(SEARCH("integrar",P2)>0,"Sim","Não") -> #VALUE! | AT2: =IF(S2="",TODAY()-Q2,S2-Q2) -> 15 | AU2: =VLOOKUP(X2,'pontos focais'!C:D,2,0) -> DCMD Programação de Obra | AV2: =U2-Q2 -> 8
A3: 1009 | B3: Visita Domo de Ferro | C3: Obra | D3: DCMD | E3: 46247 | F3: Monike Chaves | G3: Em Andamento | H3: Em Andamento | K3: 0202601135 | L3: SUL | M3: Maracaju | N3: Prefeitura | O3: Maracaju | P3: Por favor agilizar atendimento da Obra 0202601135. Loteamento Fortaleza III - objeto das matrículas de no 26830 e 26.833 do Cartório de Registro de Imóveis de Maracaju/MS, em atendimento aos 109 lotes, conforme consta no Projeto Elétrico e croqui da locação dos postes para a extensão da rede. | Q3: 46247 | R3: Por favor agilizar atendimento da Obra 0202601135. Loteamento Fortaleza III - objeto das matrículas de no 26830 e 26.833 do Cartório de Registro de Imóveis de Maracaju/MS, em atendimento aos 109 lotes, conforme consta no Projeto Elétrico e croqui da locação dos postes para a extensão da rede. | S3: 46269 | U3: 46259 | V3: 46283 | X3: Amanda Aparecida Teixeira dos Santos | Y3: Amanda Santos | Z3: Prefeito Calderan Gerente de Obras Ariana | AA3: Monike Chaves | AB3: Sim | AC3: Visita Domo de Ferro | AD3: 46269 | AE3: Amanda Aparecida Teixeira dos Santos | AF3: 46269 | AG3: Amanda Aparecida Teixeira dos Santos | AH3: 100 | AI3: 100 | AJ3: 100 | AN3: =VLOOKUP(M3,[1]municipios!$B:$D,3,0) -> RIO BRILHANTE | AO3: =TODAY()-E3 -> 41 | AP3: =IF(AO3<=5,"0–5 dias",IF(AO3<=15,"6–15 dias",IF(AO3<=16,"16–30 dias",IF(AO3<=30,"30–50 dias",">50 dias")))) -> >50 dias | AQ3: =IF(U3="","Dentro",(IF(IF(W3="",TODAY(),W3)<=U3,"Dentro","Fora"))) -> Fora | AR3: =IF(U3="","Não risco",IF((TODAY()-U3)<=7,"Risco","Não risco")) -> Não risco | AS3: =IF(SEARCH("integrar",P3)>0,"Sim","Não") -> #VALUE! | AT3: =IF(S3="",TODAY()-Q3,S3-Q3) -> 22 | AU3: =VLOOKUP(X3,'pontos focais'!C:D,2,0) -> DCMD Programação de Obra | AV3: =U3-Q3 -> 12
A4: 1012 | B4: Visita Domo de Ferro | C4: Obra | D4: DCMD | E4: 46237 | F4: Monike Chaves | G4: Em Andamento | H4: Em Andamento | K4: 0402600456 | L4: SUL | M4: Aral Moreira | N4: Prefeitura | O4: Aral Moreira | P4: PREZADOS 1053824, NÃO FOI ATENDIDO A REDE DO LOTEAMENTO, ANEXO NO PROJETO TEM OS DOCUMENTOS NECESSARIOS PARA ATENDIMENTO, BEM COMO LEI DE CRIAÇÃO. A ENTREGA DAS CASAS SERIAM NO MÊS DE AGOSTO. | Q4: 46262 | R4: Obra 0402600456 - programação de obra | S4: 46269 | T4: PROGRAMADA PARA 18/09 | U4: 46295 | V4: 46283 | X4: Amanda Aparecida Teixeira dos Santos | Y4: Amanda Santos | Z4: PREFEITA ELAINE | AB4: Sim | AC4: Visita Domo de Ferro | AD4: 46269 | AE4: Amanda Aparecida Teixeira dos Santos | AF4: 46269 | AG4: Amanda Aparecida Teixeira dos Santos | AH4: 100 | AI4: 100 | AJ4: 100 | AN4: =VLOOKUP(M4,[1]municipios!$B:$D,3,0) -> PONTA PORA | AO4: =TODAY()-E4 -> 51 | AP4: =IF(AO4<=5,"0–5 dias",IF(AO4<=15,"6–15 dias",IF(AO4<=16,"16–30 dias",IF(AO4<=30,"30–50 dias",">50 dias")))) -> >50 dias | AQ4: =IF(U4="","Dentro",(IF(IF(W4="",TODAY(),W4)<=U4,"Dentro","Fora"))) -> Dentro | AR4: =IF(U4="","Não risco",IF((TODAY()-U4)<=7,"Risco","Não risco")) -> Risco | AS4: =IF(SEARCH("integrar",P4)>0,"Sim","Não") -> #VALUE! | AT4: =IF(S4="",TODAY()-Q4,S4-Q4) -> 7 | AU4: =VLOOKUP(X4,'pontos focais'!C:D,2,0) -> DCMD Programação de Obra | AV4: =U4-Q4 -> 33
A5: 1016 | B5: Visita Domo de Ferro | C5: Atendimento Comercial | D5: DESC | E5: 46247 | F5: Marcelly Arce Avalo Franca | G5: Em Andamento | H5: Em Andamento | K5: 0452600171 | L5: CENTRO | M5: Paraíso das Águas | N5: Diretoria | O5: Paraíso das Águas | P5: OBRA: 0452600171 - ESCOPO: 40 METROS DE EXTENSÃO DE REDE + PONTO DE ENTREGA. PRAZO: 120 DIAS EXPECTATIVA DO CLIENTE: 11/09 CLIENTE SOLICITA PRIORIDADE, ATUALMENTE OPERANDO COM GERADOR. | Q5: 46275 | R5: gerar os de ligação e programar pra 11/09 | S5: 46275 | T5: OS DE LIGAÇÃO GERADAS PEDIDO PROGRAMAÇÃO PARA 11/09, AGUARDANDO CONFIRMAÇÃO | U5: 46276 | V5: 46276 | X5: Marcelly Arce Avalo Franca | Y5: Marcelly Franca | AA5: Thamara Araujo Canteiro Collombelli | AB5: Sim | AC5: Visita Domo de Ferro | AD5: 46275 | AE5: Marcelly Arce Avalo Franca | AF5: 46275 | AG5: Marcelly Arce Avalo Franca | AH5: 100 | AI5: 100 | AJ5: 100 | AN5: =VLOOKUP(M5,[1]municipios!$B:$D,3,0) -> COSTA RICA | AO5: =TODAY()-E5 -> 41 | AP5: =IF(AO5<=5,"0–5 dias",IF(AO5<=15,"6–15 dias",IF(AO5<=16,"16–30 dias",IF(AO5<=30,"30–50 dias",">50 dias")))) -> >50 dias | AQ5: =IF(U5="","Dentro",(IF(IF(W5="",TODAY(),W5)<=U5,"Dentro","Fora"))) -> Fora | AR5: =IF(U5="","Não risco",IF((TODAY()-U5)<=7,"Risco","Não risco")) -> Não risco | AS5: =IF(SEARCH("integrar",P5)>0,"Sim","Não") -> #VALUE! | AT5: =IF(S5="",TODAY()-Q5,S5-Q5) -> 0 | AU5: =VLOOKUP(X5,'pontos focais'!C:D,2,0) -> DESC Agentes de Relacionamento | AV5: =U5-Q5 -> 1
A6: 1016 | B6: Visita Domo de Ferro | C6: Obra | D6: DCMD | E6: 46247 | F6: Marcelly Arce Avalo Franca | G6: Em Andamento | H6: Finalizada | K6: 0452600171 | L6: CENTRO | M6: Paraíso das Águas | N6: Diretoria | O6: Paraíso das Águas | P6: OBRA: 0452600171 - ESCOPO: 40 METROS DE EXTENSÃO DE REDE + PONTO DE ENTREGA. PRAZO: 120 DIAS EXPECTATIVA DO CLIENTE: 11/09 CLIENTE SOLICITA PRIORIDADE, ATUALMENTE OPERANDO COM GERADOR. | Q6: 46248 | R6: Verificar cronograma e executar com o prioridade a obra. | S6: 46280 | U6: 46276 | V6: 46274 | X6: Amanda Aparecida Teixeira dos Santos | Y6: Amanda Santos | AA6: Thamara Araujo Canteiro Collombelli | AB6: Sim | AC6: Visita Domo de Ferro | AD6: 46280 | AE6: Amanda Aparecida Teixeira dos Santos | AF6: 46280 | AG6: Amanda Aparecida Teixeira dos Santos | AH6: 100 | AI6: 100 | AJ6: 100 | AN6: =VLOOKUP(M6,[1]municipios!$B:$D,3,0) -> COSTA RICA | AO6: =TODAY()-E6 -> 41 | AP6: =IF(AO6<=5,"0–5 dias",IF(AO6<=15,"6–15 dias",IF(AO6<=16,"16–30 dias",IF(AO6<=30,"30–50 dias",">50 dias")))) -> >50 dias | AQ6: =IF(U6="","Dentro",(IF(IF(W6="",TODAY(),W6)<=U6,"Dentro","Fora"))) -> Fora | AR6: =IF(U6="","Não risco",IF((TODAY()-U6)<=7,"Risco","Não risco")) -> Não risco | AS6: =IF(SEARCH("integrar",P6)>0,"Sim","Não") -> #VALUE! | AT6: =IF(S6="",TODAY()-Q6,S6-Q6) -> 32 | AU6: =VLOOKUP(X6,'pontos focais'!C:D,2,0) -> DCMD Programação de Obra | AV6: =U6-Q6 -> 28
A7: 1022 | B7: Visita Domo de Ferro | C7: Qualidade | D7: DEOP | E7: 46083 | F7: Julio Cesar dos Santos Antonelo | G7: Em Andamento | H7: Não Iniciada | J7: 30723 | L7: NORTE | M7: Corumbá | N7: Diretoria | O7: Corumbá | P7: Em 02/03/2026 - realizada reunião presencial na Energisa com os diretores da SANESUL para tratar da qualidade de fornecimento das unidades de Corumbá. Conforme documento anexo, cliente reclama de constantes oscilações no fornecimento de energia elétrica nas unidades de Corumbá. | Q7: 46226 | R7: 07/08/2026: Instalar medição nas 2 UC's prioritárias até dia 14/08/2026 14/08/2026: Instalar medição nas 2 UC's prioritárias até dia 18/08/2026. Necessário envolver o time da Gleistuany (GEST) | S7: 46269 | X7: Luan Henrique Soares Diniz Afonso | Y7: Gabriella Domingo | Z7: RENATO MARCILIO DA SILVA | AA7: Julio Cesar dos Santos Antonelo | AB7: Sim | AC7: Visita Domo de Ferro | AD7: 46269 | AE7: Gabriella Amorim Domingo | AF7: 46269 | AG7: Gabriella Amorim Domingo | AH7: 100 | AI7: 100 | AJ7: 100 | AN7: =VLOOKUP(M7,[1]municipios!$B:$D,3,0) -> CORUMBA | AO7: =TODAY()-E7 -> 205 | AP7: =IF(AO7<=5,"0–5 dias",IF(AO7<=15,"6–15 dias",IF(AO7<=16,"16–30 dias",IF(AO7<=30,"30–50 dias",">50 dias")))) -> >50 dias | AQ7: =IF(U7="","Dentro",(IF(IF(W7="",TODAY(),W7)<=U7,"Dentro","Fora"))) -> Dentro | AR7: =IF(U7="","Não risco",IF((TODAY()-U7)<=7,"Risco","Não risco")) -> Não risco | AS7: =IF(SEARCH("integrar",P7)>0,"Sim","Não") -> #VALUE! | AT7: =IF(S7="",TODAY()-Q7,S7-Q7) -> 43 | AU7: =VLOOKUP(X7,'pontos focais'!C:D,2,0) -> DEOP Qualidade | AV7: =U7-Q7 -> -46226
A8: 1027 | B8: Visita Domo de Ferro | C8: Obra | D8: DCMD | E8: 46265 | F8: Monike Chaves | G8: Em Andamento | H8: Em Andamento | K8: 0402600390 | L8: SUL | M8: Antônio João | N8: Prefeitura | O8: Antônio João | P8: Prefeito de Antonio João pedindo prioridade no atendimento dessa obra, pois a obra interna oi paralisada. | Q8: 46252 | S8: 46280 | T8: Reprogramada para 24/09 - devido a contingencia | U8: 46265 | V8: 46289 | X8: Amanda Aparecida Teixeira dos Santos | Y8: Amanda Santos | Z8: Prefeito Marcelo | AB8: Sim | AC8: Visita Domo de Ferro | AD8: 46280 | AE8: Amanda Aparecida Teixeira dos Santos | AF8: 46280 | AG8: Amanda Aparecida Teixeira dos Santos | AH8: 100 | AI8: 100 | AJ8: 100 | AN8: =VLOOKUP(M8,[1]municipios!$B:$D,3,0) -> PONTA PORA | AO8: =TODAY()-E8 -> 23 | AP8: =IF(AO8<=5,"0–5 dias",IF(AO8<=15,"6–15 dias",IF(AO8<=16,"16–30 dias",IF(AO8<=30,"30–50 dias",">50 dias")))) -> 30–50 dias | AQ8: =IF(U8="","Dentro",(IF(IF(W8="",TODAY(),W8)<=U8,"Dentro","Fora"))) -> Fora | AR8: =IF(U8="","Não risco",IF((TODAY()-U8)<=7,"Risco","Não risco")) -> Não risco | AS8: =IF(SEARCH("integrar",P8)>0,"Sim","Não") -> #VALUE! | AT8: =IF(S8="",TODAY()-Q8,S8-Q8) -> 28 | AU8: =VLOOKUP(X8,'pontos focais'!C:D,2,0) -> DCMD Programação de Obra | AV8: =U8-Q8 -> 13
A9: 1032 | B9: Visita Domo de Ferro | C9: Obra | D9: DCMD | E9: 46211 | F9: Monike Chaves | G9: Finalizada | H9: Finalizada | K9: 0502600521 | L9: SUL | M9: Tacuru | N9: Prefeitura | O9: Tacuru | P9: Por favor verificar possibilidade de agilizar atendimento da Obra 0502600521. | Q9: 46252 | R9: Por favor verificar possibilidade de agilizar atendimento da Obra 0502600521. | S9: 46267 | T9: OBRA CONCLUIDA 21/08 | U9: 46337 | W9: 46255 | X9: Amanda Aparecida Teixeira dos Santos | Y9: Amanda Santos | Z9: Prefeito Rogério | AA9: Jonas Ortiz Rudis | AB9: Sim | AC9: Visita Domo de Ferro | AD9: 46267 | AE9: Amanda Aparecida Teixeira dos Santos | AF9: 46267 | AG9: Amanda Aparecida Teixeira dos Santos | AH9: 100 | AI9: 100 | AJ9: 100 | AN9: =VLOOKUP(M9,[1]municipios!$B:$D,3,0) -> NAVIRAI | AO9: =TODAY()-E9 -> 77 | AP9: =IF(AO9<=5,"0–5 dias",IF(AO9<=15,"6–15 dias",IF(AO9<=16,"16–30 dias",IF(AO9<=30,"30–50 dias",">50 dias")))) -> >50 dias | AQ9: =IF(U9="","Dentro",(IF(IF(W9="",TODAY(),W9)<=U9,"Dentro","Fora"))) -> Dentro | AR9: =IF(U9="","Não risco",IF((TODAY()-U9)<=7,"Risco","Não risco")) -> Risco | AS9: =IF(SEARCH("integrar",P9)>0,"Sim","Não") -> #VALUE! | AT9: =IF(S9="",TODAY()-Q9,S9-Q9) -> 15 | AU9: =VLOOKUP(X9,'pontos focais'!C:D,2,0) -> DCMD Programação de Obra | AV9: =U9-Q9 -> 85
A10: 1036 | B10: Visita Domo de Ferro | C10: Manutenção | D10: DCMD | E10: 46252 | F10: Giovani Moura Sousa | G10: Em Andamento | H10: Não Iniciada | L10: CENTRO | M10: Campo Grande | N10: Câmara | O10: Campo Grande | P10: Solicita substituião do poste quebrado a Rua Grace Kelly, 306 | Q10: 46253 | R10: Programar levantamento para substituição de poste quebrado. Rua Grace Kelly, nº 306 - Bairro Jardim Colibri - Campo Grande/MS. | X10: Evair Rogerio da Conceicao | Z10: Vereador Beto Avelar | AA10: Giovani Moura Sousa | AB10: Sim | AC10: Visita Domo de Ferro | AD10: 46253 | AE10: Wander Idalino Machado | AF10: 46253 | AG10: Wander Idalino Machado | AH10: 25 | AI10: 25 | AJ10: 12.5 | AK10: Manutenção e Poda | AM10: DCMD - PODA E MANUTENÇÃO | AN10: =VLOOKUP(M10,[1]municipios!$B:$D,3,0) -> CAMPO GRANDE | AO10: =TODAY()-E10 -> 36 | AP10: =IF(AO10<=5,"0–5 dias",IF(AO10<=15,"6–15 dias",IF(AO10<=16,"16–30 dias",IF(AO10<=30,"30–50 dias",">50 dias")))) -> >50 dias | AQ10: =IF(U10="","Dentro",(IF(IF(W10="",TODAY(),W10)<=U10,"Dentro","Fora"))) -> Dentro | AR10: =IF(U10="","Não risco",IF((TODAY()-U10)<=7,"Risco","Não risco")) -> Não risco | AS10: =IF(SEARCH("integrar",P10)>0,"Sim","Não") -> #VALUE! | AT10: =IF(S10="",TODAY()-Q10,S10-Q10) -> 35 | AU10: =VLOOKUP(X10,'pontos focais'!C:D,2,0) -> DCMD Manutenção | AV10: =U10-Q10 -> -46253
A11: 1043 | B11: Visita Domo de Ferro | C11: Obra | D11: DCMD | E11: 46253 | F11: Dian Cleiton de Brito | G11: Finalizada | H11: Finalizada | K11: 0302600251 | L11: SUL | M11: Bataguassu | N11: Assembleia Legislativa | O11: Bataguassu | P11: Deputado e Prefeita solicitam a relocação com urgÊncia considerando a paralização das obras de pavimentação. Expect 31/08/26; | Q11: 46255 | R11: Por favor, disponibilizar orçamento ao cliente. | S11: 46273 | T11: Obra gerada o boleto na UC conforme solicitado e liberada. | U11: 46265 | W11: 46199 | X11: Bruna Victoria Rodrigues Ricardes | Y11: Bruna Ricardes | Z11: Caravina - Deputado Wanderleia - Prefeita Carol - Secretaria de Adm | AA11: Dian Cleiton de Brito | AB11: Sim | AC11: Visita Domo de Ferro | AD11: 46273 | AE11: Bruna Victoria Rodrigues Ricardes | AF11: 46273 | AG11: Bruna Victoria Rodrigues Ricardes | AH11: 100 | AI11: 100 | AJ11: 100 | AN11: =VLOOKUP(M11,[1]municipios!$B:$D,3,0) -> NOVA ANDRADINA | AO11: =TODAY()-E11 -> 35 | AP11: =IF(AO11<=5,"0–5 dias",IF(AO11<=15,"6–15 dias",IF(AO11<=16,"16–30 dias",IF(AO11<=30,"30–50 dias",">50 dias")))) -> >50 dias | AQ11: =IF(U11="","Dentro",(IF(IF(W11="",TODAY(),W11)<=U11,"Dentro","Fora"))) -> Dentro | AR11: =IF(U11="","Não risco",IF((TODAY()-U11)<=7,"Risco","Não risco")) -> Não risco | AS11: =IF(SEARCH("integrar",P11)>0,"Sim","Não") -> #VALUE! | AT11: =IF(S11="",TODAY()-Q11,S11-Q11) -> 18 | AU11: =VLOOKUP(X11,'pontos focais'!C:D,2,0) -> DCMD Orçamento e Projetos | AV11: =U11-Q11 -> 10
A12: 1045 | B12: Visita Domo de Ferro | C12: Obra | D12: DCMD | E12: 46254 | F12: Dian Cleiton de Brito | G12: Em Andamento | H12: Em Andamento | K12: 050-26-00571 | L12: SUL | M12: Itaquiraí | N12: Governo do Estado | O12: Itaquiraí | P12: Governador solicitou agilizar obra de atendimento ao Cliente. Expec: 20/09/26; NELSON TUTIDA CPF: 245.245.499-00 IE: 28.790.825-9 FAZ MEIO SECULO, ZONA RURAL, ITAQUIRAÍ - MS PROJETO 23623/26 UC: 3877911 CUSD 13524 OBRA: 050-26-00571 | Q12: 46253 | R12: Liberar programação da Obra 0502600571 | S12: 46280 | U12: 46284 | V12: 46283 | X12: Amanda Aparecida Teixeira dos Santos | Y12: Amanda Santos | Z12: Eduardo Riedel - Governador Paulo Roberto - DPRE | AA12: Dian Cleiton de Brito | AB12: Sim | AC12: Visita Domo de Ferro | AD12: 46280 | AE12: Amanda Aparecida Teixeira dos Santos | AF12: 46280 | AG12: Amanda Aparecida Teixeira dos Santos | AH12: 100 | AI12: 100 | AJ12: 100 | AN12: =VLOOKUP(M12,[1]municipios!$B:$D,3,0) -> NAVIRAI | AO12: =TODAY()-E12 -> 34 | AP12: =IF(AO12<=5,"0–5 dias",IF(AO12<=15,"6–15 dias",IF(AO12<=16,"16–30 dias",IF(AO12<=30,"30–50 dias",">50 dias")))) -> >50 dias | AQ12: =IF(U12="","Dentro",(IF(IF(W12="",TODAY(),W12)<=U12,"Dentro","Fora"))) -> Fora | AR12: =IF(U12="","Não risco",IF((TODAY()-U12)<=7,"Risco","Não risco")) -> Risco | AS12: =IF(SEARCH("integrar",P12)>0,"Sim","Não") -> #VALUE! | AT12: =IF(S12="",TODAY()-Q12,S12-Q12) -> 27 | AU12: =VLOOKUP(X12,'pontos focais'!C:D,2,0) -> DCMD Programação de Obra | AV12: =U12-Q12 -> 31
A13: 1057 | B13: Visita Domo de Ferro | C13: Obra | D13: DCMD | E13: 46255 | F13: Dian Cleiton de Brito | G13: Em Andamento | H13: Em Andamento | K13: 0252600281 | L13: NORTE | M13: Miranda | N13: Diretoria | O13: Miranda | P13: Presidente solicitou para agilizar obra de extensão de rede para atendimento de Eletroposto. Expectativa: 20/09/26 | Q13: 46258 | R13: Obra 0252600281 - por favor agilizar programação. | S13: 46269 | T13: Obra programada para finalizar 20/09 | U13: 46285 | V13: 46285 | X13: Amanda Aparecida Teixeira dos Santos | Y13: Amanda Santos | Z13: Paulo Roberto | AA13: Dian Cleiton de Brito | AB13: Sim | AC13: Visita Domo de Ferro | AD13: 46269 | AE13: Amanda Aparecida Teixeira dos Santos | AF13: 46269 | AG13: Amanda Aparecida Teixeira dos Santos | AH13: 100 | AI13: 100 | AJ13: 100 | AN13: =VLOOKUP(M13,[1]municipios!$B:$D,3,0) -> AQUIDAUANA | AO13: =TODAY()-E13 -> 33 | AP13: =IF(AO13<=5,"0–5 dias",IF(AO13<=15,"6–15 dias",IF(AO13<=16,"16–30 dias",IF(AO13<=30,"30–50 dias",">50 dias")))) -> >50 dias | AQ13: =IF(U13="","Dentro",(IF(IF(W13="",TODAY(),W13)<=U13,"Dentro","Fora"))) -> Fora | AR13: =IF(U13="","Não risco",IF((TODAY()-U13)<=7,"Risco","Não risco")) -> Risco | AS13: =IF(SEARCH("integrar",P13)>0,"Sim","Não") -> #VALUE! | AT13: =IF(S13="",TODAY()-Q13,S13-Q13) -> 11 | AU13: =VLOOKUP(X13,'pontos focais'!C:D,2,0) -> DCMD Programação de Obra | AV13: =U13-Q13 -> 27
A14: 1060 | B14: Visita Domo de Ferro | C14: Obra | D14: DCMD | E14: 46258 | F14: Aline da Silva Mesquita | G14: Em Andamento | H14: Em Andamento | K14: 0102601321 | L14: CENTRO | M14: Ribas do Rio Pardo | N14: Prefeitura | O14: Ribas do Rio Pardo | P14: Prefeito de Ribas me pediu para agilizar essas obras a seguir pra esta semana urgente. | Q14: 46258 | R14: agilizar obra, pra esta semana urgente. | S14: 46280 | T14: Programada para 14/10 | U14: 46265 | V14: 46309 | X14: Amanda Aparecida Teixeira dos Santos | Y14: Amanda Santos | AB14: Sim | AC14: Visita Domo de Ferro | AD14: 46280 | AE14: Amanda Aparecida Teixeira dos Santos | AF14: 46280 | AG14: Amanda Aparecida Teixeira dos Santos | AH14: 100 | AI14: 100 | AJ14: 100 | AN14: =VLOOKUP(M14,[1]municipios!$B:$D,3,0) -> CAMPO GRANDE INTERIOR | AO14: =TODAY()-E14 -> 30 | AP14: =IF(AO14<=5,"0–5 dias",IF(AO14<=15,"6–15 dias",IF(AO14<=16,"16–30 dias",IF(AO14<=30,"30–50 dias",">50 dias")))) -> 30–50 dias | AQ14: =IF(U14="","Dentro",(IF(IF(W14="",TODAY(),W14)<=U14,"Dentro","Fora"))) -> Fora | AR14: =IF(U14="","Não risco",IF((TODAY()-U14)<=7,"Risco","Não risco")) -> Não risco | AS14: =IF(SEARCH("integrar",P14)>0,"Sim","Não") -> #VALUE! | AT14: =IF(S14="",TODAY()-Q14,S14-Q14) -> 22 | AU14: =VLOOKUP(X14,'pontos focais'!C:D,2,0) -> DCMD Programação de Obra | AV14: =U14-Q14 -> 7
A15: 1061 | B15: Visita Domo de Ferro | C15: Obra | D15: DCMD | E15: 46258 | F15: Aline da Silva Mesquita | G15: Finalizada | H15: Finalizada | K15: 0102601427 | L15: CENTRO | M15: Ribas do Rio Pardo | N15: Prefeitura | O15: Ribas do Rio Pardo | P15: Prefeito de Ribas me pediu para agilizar essas obras a seguir pra esta semana urgente | Q15: 46258 | R15: agilizar obra pra esta semana urgente. | S15: 46269 | T15: Obra concluída 28/08 | U15: 46265 | W15: 46262 | X15: Amanda Aparecida Teixeira dos Santos | Y15: Amanda Santos | AB15: Sim | AC15: Visita Domo de Ferro | AD15: 46269 | AE15: Amanda Aparecida Teixeira dos Santos | AF15: 46269 | AG15: Amanda Aparecida Teixeira dos Santos | AH15: 100 | AI15: 100 | AJ15: 100 | AN15: =VLOOKUP(M15,[1]municipios!$B:$D,3,0) -> CAMPO GRANDE INTERIOR | AO15: =TODAY()-E15 -> 30 | AP15: =IF(AO15<=5,"0–5 dias",IF(AO15<=15,"6–15 dias",IF(AO15<=16,"16–30 dias",IF(AO15<=30,"30–50 dias",">50 dias")))) -> 30–50 dias | AQ15: =IF(U15="","Dentro",(IF(IF(W15="",TODAY(),W15)<=U15,"Dentro","Fora"))) -> Dentro | AR15: =IF(U15="","Não risco",IF((TODAY()-U15)<=7,"Risco","Não risco")) -> Não risco | AS15: =IF(SEARCH("integrar",P15)>0,"Sim","Não") -> #VALUE! | AT15: =IF(S15="",TODAY()-Q15,S15-Q15) -> 11 | AU15: =VLOOKUP(X15,'pontos focais'!C:D,2,0) -> DCMD Programação de Obra | AV15: =U15-Q15 -> 7
A16: 1062 | B16: Visita Domo de Ferro | C16: Obra | D16: DCMD | E16: 46258 | F16: Aline da Silva Mesquita | G16: Em Andamento | H16: Não Iniciada | K16: 0102601240 | L16: CENTRO | M16: Ribas do Rio Pardo | N16: Prefeitura | O16: Ribas do Rio Pardo | P16: Prefeito de Ribas me pediu para agilizar essas obras a seguir pra esta semana urgente | Q16: 46275 | R16: Obra 0102601240. Devolver ao SPRO, projeto não condiz com a situação em campo. No projeto pede a desativação de uma rede mas ela não é existente em campo. | S16: 46276 | U16: 46442 | X16: Evelyn Carlos Benites | Y16: Rafaela Almeida | AB16: Sim | AC16: Visita Domo de Ferro | AD16: 46276 | AE16: Rafaela Mattos de Almeida | AF16: 46276 | AG16: Rafaela Mattos de Almeida | AH16: 100 | AI16: 100 | AJ16: 100 | AN16: =VLOOKUP(M16,[1]municipios!$B:$D,3,0) -> CAMPO GRANDE INTERIOR | AO16: =TODAY()-E16 -> 30 | AP16: =IF(AO16<=5,"0–5 dias",IF(AO16<=15,"6–15 dias",IF(AO16<=16,"16–30 dias",IF(AO16<=30,"30–50 dias",">50 dias")))) -> 30–50 dias | AQ16: =IF(U16="","Dentro",(IF(IF(W16="",TODAY(),W16)<=U16,"Dentro","Fora"))) -> Dentro | AR16: =IF(U16="","Não risco",IF((TODAY()-U16)<=7,"Risco","Não risco")) -> Risco | AS16: =IF(SEARCH("integrar",P16)>0,"Sim","Não") -> #VALUE! | AT16: =IF(S16="",TODAY()-Q16,S16-Q16) -> 1 | AU16: =VLOOKUP(X16,'pontos focais'!C:D,2,0) -> DCMD Orçamento e Projetos | AV16: =U16-Q16 -> 167
A17: 1064 | B17: Visita Domo de Ferro | C17: Informação | D17: DESC | E17: 46258 | F17: Aline da Silva Mesquita | G17: Em Andamento | H17: Não Iniciada | K17: 0702600176 | L17: NORTE | M17: Coxim | N17: Prefeitura | O17: Coxim | P17: Availdo vai entrar em contato. Obra liberada, pedir prioridade via central, SOLICITADA PELA ALINE MESQUITA | Q17: 46258 | R17: Availdo vai entrar em contato, para maior entendimento, trata-se de duas obras 0702600176 e 0702600108. Aline Mesquita descreveu: Porem segue algumas observações; a Obra ainda não esta em execução mesmo ter saído sem custo, provavelmente o que esta pendente é o contrato de demanda com os grandes clientes. o posto de transformação também esta pendente a solicitação de comissionamento. | S17: 46273 | V17: 46261 | X17: Availdo Taveira de Oliveira | Y17: Gabriella Domingo | AA17: Availdo Taveira de Oliveira | AB17: Sim | AC17: Prefeitura | AD17: 46273 | AE17: Gabriella Amorim Domingo | AF17: 46273 | AG17: Gabriella Amorim Domingo | AH17: 100 | AI17: 100 | AJ17: 100 | AN17: =VLOOKUP(M17,[1]municipios!$B:$D,3,0) -> COXIM | AO17: =TODAY()-E17 -> 30 | AP17: =IF(AO17<=5,"0–5 dias",IF(AO17<=15,"6–15 dias",IF(AO17<=16,"16–30 dias",IF(AO17<=30,"30–50 dias",">50 dias")))) -> 30–50 dias | AQ17: =IF(U17="","Dentro",(IF(IF(W17="",TODAY(),W17)<=U17,"Dentro","Fora"))) -> Dentro | AR17: =IF(U17="","Não risco",IF((TODAY()-U17)<=7,"Risco","Não risco")) -> Não risco | AS17: =IF(SEARCH("integrar",P17)>0,"Sim","Não") -> #VALUE! | AT17: =IF(S17="",TODAY()-Q17,S17-Q17) -> 15 | AU17: =VLOOKUP(X17,'pontos focais'!C:D,2,0) -> DESC Agentes de Relacionamento | AV17: =U17-Q17 -> -46258
A18: 1064 | B18: Visita Domo de Ferro | C18: Obra | D18: DCMD | E18: 46258 | F18: Aline da Silva Mesquita | G18: Em Andamento | H18: Em Andamento | K18: 0702600176 | L18: NORTE | M18: Coxim | N18: Prefeitura | O18: Coxim | P18: Availdo vai entrar em contato. Obra liberada, pedir prioridade via central, SOLICITADA PELA ALINE MESQUITA | Q18: 46258 | R18: Obra liberada, liberar programação, obra necessaria ser atendida com urgencia. Demanda DPRE São duas obras 0702600176 e 0702600108 | S18: 46280 | T18: Reprogramada para 26/09 - devido a contingencia | U18: 46295 | V18: 46291 | X18: Amanda Aparecida Teixeira dos Santos | Y18: Amanda Santos | AA18: Availdo Taveira de Oliveira | AB18: Sim | AC18: Prefeitura | AD18: 46280 | AE18: Amanda Aparecida Teixeira dos Santos | AF18: 46280 | AG18: Amanda Aparecida Teixeira dos Santos | AH18: 100 | AI18: 100 | AJ18: 100 | AN18: =VLOOKUP(M18,[1]municipios!$B:$D,3,0) -> COXIM | AO18: =TODAY()-E18 -> 30 | AP18: =IF(AO18<=5,"0–5 dias",IF(AO18<=15,"6–15 dias",IF(AO18<=16,"16–30 dias",IF(AO18<=30,"30–50 dias",">50 dias")))) -> 30–50 dias | AQ18: =IF(U18="","Dentro",(IF(IF(W18="",TODAY(),W18)<=U18,"Dentro","Fora"))) -> Dentro | AR18: =IF(U18="","Não risco",IF((TODAY()-U18)<=7,"Risco","Não risco")) -> Risco | AS18: =IF(SEARCH("integrar",P18)>0,"Sim","Não") -> #VALUE! | AT18: =IF(S18="",TODAY()-Q18,S18-Q18) -> 22 | AU18: =VLOOKUP(X18,'pontos focais'!C:D,2,0) -> DCMD Programação de Obra | AV18: =U18-Q18 -> 37
A19: 1066 | B19: Visita Domo de Ferro | C19: Obra | D19: DCMD | E19: 46254 | F19: Aline da Silva Mesquita | G19: Em Andamento | H19: Finalizada | L19: CENTRO | M19: Ribas do Rio Pardo | N19: Diretoria | O19: Ribas do Rio Pardo | P19: Trata-se do novo prédio da Policia militar. Obra por parte do cliente concluída e comissionada. | Q19: 46259 | R19: Agilizar o orçamento para seguirmos com a elaboração dos contratos | S19: 46273 | U19: 46265 | X19: Bruna Victoria Rodrigues Ricardes | Y19: Bruna Ricardes | Z19: Denise Simoes | AB19: Sim | AC19: Visita Domo de Ferro | AD19: 46273 | AE19: Bruna Victoria Rodrigues Ricardes | AF19: 46273 | AG19: Bruna Victoria Rodrigues Ricardes | AH19: 100 | AI19: 100 | AJ19: 100 | AN19: =VLOOKUP(M19,[1]municipios!$B:$D,3,0) -> CAMPO GRANDE INTERIOR | AO19: =TODAY()-E19 -> 34 | AP19: =IF(AO19<=5,"0–5 dias",IF(AO19<=15,"6–15 dias",IF(AO19<=16,"16–30 dias",IF(AO19<=30,"30–50 dias",">50 dias")))) -> >50 dias | AQ19: =IF(U19="","Dentro",(IF(IF(W19="",TODAY(),W19)<=U19,"Dentro","Fora"))) -> Fora | AR19: =IF(U19="","Não risco",IF((TODAY()-U19)<=7,"Risco","Não risco")) -> Não risco | AS19: =IF(SEARCH("integrar",P19)>0,"Sim","Não") -> #VALUE! | AT19: =IF(S19="",TODAY()-Q19,S19-Q19) -> 14 | AU19: =VLOOKUP(X19,'pontos focais'!C:D,2,0) -> DCMD Orçamento e Projetos | AV19: =U19-Q19 -> 6
A20: 1066 | B20: Visita Domo de Ferro | C20: Obra | D20: DESC | E20: 46254 | F20: Aline da Silva Mesquita | G20: Em Andamento | H20: Não Iniciada | I20: SECRETARIA DE ESTADO DE JUSTIÇA E SEGURANÇA PÚBLICA | K20: 010260168 | L20: CENTRO | M20: Ribas do Rio Pardo | N20: Diretoria | O20: Ribas do Rio Pardo | P20: Trata-se do novo prédio da Policia militar. Obra por parte do cliente concluída e comissionada. | Q20: 46275 | R20: Obra 010260168 - Projeto anexado. Por favor seguir com a elaboração dos contratos. Orçamento enviado para o cliente. | X20: Marcelly Arce Avalo Franca | Z20: Denise Simoes | AB20: Sim | AC20: Visita Domo de Ferro | AD20: 46276 | AE20: Wander Idalino Machado | AF20: 46276 | AG20: Wander Idalino Machado | AH20: 100 | AI20: 100 | AJ20: 50 | AK20: Relacionamento com cliente | AM20: CGCP | AN20: =VLOOKUP(M20,[1]municipios!$B:$D,3,0) -> CAMPO GRANDE INTERIOR | AO20: =TODAY()-E20 -> 34 | AP20: =IF(AO20<=5,"0–5 dias",IF(AO20<=15,"6–15 dias",IF(AO20<=16,"16–30 dias",IF(AO20<=30,"30–50 dias",">50 dias")))) -> >50 dias | AQ20: =IF(U20="","Dentro",(IF(IF(W20="",TODAY(),W20)<=U20,"Dentro","Fora"))) -> Dentro | AR20: =IF(U20="","Não risco",IF((TODAY()-U20)<=7,"Risco","Não risco")) -> Não risco | AS20: =IF(SEARCH("integrar",P20)>0,"Sim","Não") -> #VALUE! | AT20: =IF(S20="",TODAY()-Q20,S20-Q20) -> 13 | AU20: =VLOOKUP(X20,'pontos focais'!C:D,2,0) -> DESC Agentes de Relacionamento | AV20: =U20-Q20 -> -46275
A21: 1067 | B21: Visita Domo de Ferro | C21: Poda | D21: DCMD | E21: 46265 | F21: Giovani Moura Sousa | G21: Finalizada | H21: Finalizada | J21: 1.368.792.051-47 | L21: SUL | M21: Dourados | N21: Câmara | O21: Dourados | P21: PODA E SUPRESSAO DA ARVORE UC136879205147 RUA DAS FIGUEIRAS 810 - JARDIM COLIBRI, COM AUTORIZAÇÃO DO IMAM, CONFORME ANEXO. NECESSARIO COM URGENCIA ARVORE ESTA CAINDO E NO LOCAL NAO PODE FICAR SEM ENERGIA DEVIDO A SER UM CLIENTE VIP ENFERMO COM USO DE EQUIPAMENTO ESSENCIAL. | Q21: 46259 | R21: PODA E SUPRESSAO DA ARVORE UC136879205147 RUA DAS FIGUEIRAS 810 - JARDIM COLIBRI, COM AUTORIZAÇÃO DO IMAM, CONFORME ANEXO. NECESSARIO COM URGENCIA ARVORE ESTA CAINDO E NO LOCAL NAO PODE FICAR SEM ENERGIA DEVIDO A SER UM CLIENTE VIP ENFERMO COM USO DE EQUIPAMENTO ESSENCIAL. | S21: 46265 | T21: Supressão realizada. | X21: Evair Rogerio da Conceicao | Y21: Evair Conceicao | AB21: Sim | AC21: Visita Domo de Ferro | AD21: 46265 | AE21: Evair Rogerio da Conceicao | AF21: 46265 | AG21: Evair Rogerio da Conceicao | AH21: 25 | AI21: 25 | AJ21: 25 | AN21: =VLOOKUP(M21,[1]municipios!$B:$D,3,0) -> DOURADOS | AO21: =TODAY()-E21 -> 23 | AP21: =IF(AO21<=5,"0–5 dias",IF(AO21<=15,"6–15 dias",IF(AO21<=16,"16–30 dias",IF(AO21<=30,"30–50 dias",">50 dias")))) -> 30–50 dias | AQ21: =IF(U21="","Dentro",(IF(IF(W21="",TODAY(),W21)<=U21,"Dentro","Fora"))) -> Dentro | AR21: =IF(U21="","Não risco",IF((TODAY()-U21)<=7,"Risco","Não risco")) -> Não risco | AS21: =IF(SEARCH("integrar",P21)>0,"Sim","Não") -> #VALUE! | AT21: =IF(S21="",TODAY()-Q21,S21-Q21) -> 6 | AU21: =VLOOKUP(X21,'pontos focais'!C:D,2,0) -> DCMD Manutenção | AV21: =U21-Q21 -> -46259
A22: 1073 | B22: Visita Domo de Ferro | C22: Obra | D22: DCMD | E22: 46262 | F22: Dian Cleiton de Brito | G22: Finalizada | H22: Finalizada | K22: 0402600390 | L22: SUL | M22: Antônio João | N22: Assembleia Legislativa | O22: Antônio João | P22: SOLICITA AGILIZAR A REALIZAÇAO DA OBRA EXPECTATIVA 15/09. Demanda gerada em duplicidade - Obra 0402600390 - Todas as tratativas que o caso requer ocorrerá através do ID 1027. | Q22: 46262 | R22: Obra 0402600390 - Programação. | S22: 46280 | T22: Duplicado com ID 1027 | U22: 46280 | V22: 46279 | X22: Amanda Aparecida Teixeira dos Santos | Y22: Amanda Santos | Z22: PAULO ROBERTO BETO PEREIRA | AA22: Dian Cleiton de Brito | AB22: Sim | AC22: Visita Domo de Ferro | AD22: 46280 | AE22: Amanda Aparecida Teixeira dos Santos | AF22: 46280 | AG22: Amanda Aparecida Teixeira dos Santos | AH22: 100 | AI22: 100 | AJ22: 100 | AN22: =VLOOKUP(M22,[1]municipios!$B:$D,3,0) -> PONTA PORA | AO22: =TODAY()-E22 -> 26 | AP22: =IF(AO22<=5,"0–5 dias",IF(AO22<=15,"6–15 dias",IF(AO22<=16,"16–30 dias",IF(AO22<=30,"30–50 dias",">50 dias")))) -> 30–50 dias | AQ22: =IF(U22="","Dentro",(IF(IF(W22="",TODAY(),W22)<=U22,"Dentro","Fora"))) -> Fora | AR22: =IF(U22="","Não risco",IF((TODAY()-U22)<=7,"Risco","Não risco")) -> Não risco | AS22: =IF(SEARCH("integrar",P22)>0,"Sim","Não") -> #VALUE! | AT22: =IF(S22="",TODAY()-Q22,S22-Q22) -> 18 | AU22: =VLOOKUP(X22,'pontos focais'!C:D,2,0) -> DCMD Programação de Obra | AV22: =U22-Q22 -> 18
A23: 1074 | B23: Visita Domo de Ferro | C23: Obra | D23: DCMD | E23: 46295 | F23: Monike Chaves | G23: Em Andamento | H23: Em Andamento | K23: 0202600798 | L23: SUL | M23: Caarapó | N23: Prefeitura | O23: Caarapó | P23: Prefeita solicitou adiantamento da obra, em decorrecnia de obra no local. | Q23: 46265 | R23: Obra 0202600798 - programação. | S23: 46280 | T23: Mantém para 28/09 | V23: 46293 | X23: Amanda Aparecida Teixeira dos Santos | Y23: Amanda Santos | Z23: Prefeita Lurdes | AA23: Aline da Silva Mesquita | AB23: Sim | AC23: Prefeitura | AD23: 46280 | AE23: Amanda Aparecida Teixeira dos Santos | AF23: 46280 | AG23: Amanda Aparecida Teixeira dos Santos | AH23: 100 | AI23: 100 | AJ23: 100 | AN23: =VLOOKUP(M23,[1]municipios!$B:$D,3,0) -> DOURADOS | AO23: =TODAY()-E23 -> -7 | AP23: =IF(AO23<=5,"0–5 dias",IF(AO23<=15,"6–15 dias",IF(AO23<=16,"16–30 dias",IF(AO23<=30,"30–50 dias",">50 dias")))) -> 0–5 dias | AQ23: =IF(U23="","Dentro",(IF(IF(W23="",TODAY(),W23)<=U23,"Dentro","Fora"))) -> Dentro | AR23: =IF(U23="","Não risco",IF((TODAY()-U23)<=7,"Risco","Não risco")) -> Não risco | AS23: =IF(SEARCH("integrar",P23)>0,"Sim","Não") -> #VALUE! | AT23: =IF(S23="",TODAY()-Q23,S23-Q23) -> 15 | AU23: =VLOOKUP(X23,'pontos focais'!C:D,2,0) -> DCMD Programação de Obra | AV23: =U23-Q23 -> -46265
A24: 1080 | B24: Visita Domo de Ferro | C24: Obra | D24: DCMD | E24: 46267 | F24: Dian Cleiton de Brito | G24: Em Andamento | H24: Não Iniciada | I24: JOSE RODRIGUES PEREIRA | K24: 0102201031 | L24: CENTRO | M24: Bandeirantes | N24: Assembleia Legislativa | O24: Bandeirantes | P24: Proprietário da Faz Elizabeth solicita a execução da obra em execução em sua proriedade a 4 anos. precisa da execução imediata para inicio do plantio. Necessidade 15/09/26. | Q24: 46282 | R24: Obra 0102201031 Fiscalização Reprovada. Por favor avaliar o andamento pois a obra contempla a instalação de 01 religador 34.5 KV. Tratativa deve ser feita pelo SPCO, o Religador chegará em 28/09/2026. | X24: Amanda Aparecida Teixeira dos Santos | Z24: Junior Mocci Renato Câmara | AA24: Dian Cleiton de Brito | AB24: Sim | AC24: Visita Domo de Ferro | AD24: 46282 | AE24: Wander Idalino Machado | AF24: 46282 | AG24: Wander Idalino Machado | AH24: 100 | AI24: 100 | AJ24: 50 | AK24: Programação de Obras e Gestão de Materiais | AM24: DCMD - PROGRAMAÇÃO DE OBRA | AN24: =VLOOKUP(M24,[1]municipios!$B:$D,3,0) -> CAMPO GRANDE INTERIOR | AO24: =TODAY()-E24 -> 21 | AP24: =IF(AO24<=5,"0–5 dias",IF(AO24<=15,"6–15 dias",IF(AO24<=16,"16–30 dias",IF(AO24<=30,"30–50 dias",">50 dias")))) -> 30–50 dias | AQ24: =IF(U24="","Dentro",(IF(IF(W24="",TODAY(),W24)<=U24,"Dentro","Fora"))) -> Dentro | AR24: =IF(U24="","Não risco",IF((TODAY()-U24)<=7,"Risco","Não risco")) -> Não risco | AS24: =IF(SEARCH("integrar",P24)>0,"Sim","Não") -> #VALUE! | AT24: =IF(S24="",TODAY()-Q24,S24-Q24) -> 6 | AU24: =VLOOKUP(X24,'pontos focais'!C:D,2,0) -> DCMD Programação de Obra | AV24: =U24-Q24 -> -46282
A25: 1087 | B25: Visita Domo de Ferro | C25: Qualidade | D25: DEOP | E25: 46268 | F25: Dian Cleiton de Brito | G25: Em Andamento | H25: Não Iniciada | I25: RAFAEL PIZZI | J25: 2986442/2944064 | L25: CENTRO | M25: Aparecida do Taboado | N25: Prefeitura | O25: Aparecida do Taboado | P25: RECLAMAÇÃO SOBRECARGAS E ABERTURA DO TRANSFORMADOR. UC 2986442 - 200 A UC 2944064 - 200 A ligadas no mesmo transformador. ENTF 000505 | Q25: 46269 | R25: Por favor realizar os estudos para avaliação e as possíveis intervenções. Unidades consumidoras 2986442 e 2944064. Transformador ENTF 000505. | X25: Luan Henrique Soares Diniz Afonso | Z25: José Natan - Prefeito | AA25: Dian Cleiton de Brito | AB25: Sim | AC25: Visita Domo de Ferro | AD25: 46269 | AE25: Wander Idalino Machado | AF25: 46269 | AG25: Wander Idalino Machado | AH25: 100 | AI25: 100 | AJ25: 50 | AK25: Qualidade do produto | AM25: DEOP - QUALIDADE | AN25: =VLOOKUP(M25,[1]municipios!$B:$D,3,0) -> PARANAIBA | AO25: =TODAY()-E25 -> 20 | AP25: =IF(AO25<=5,"0–5 dias",IF(AO25<=15,"6–15 dias",IF(AO25<=16,"16–30 dias",IF(AO25<=30,"30–50 dias",">50 dias")))) -> 30–50 dias | AQ25: =IF(U25="","Dentro",(IF(IF(W25="",TODAY(),W25)<=U25,"Dentro","Fora"))) -> Dentro | AR25: =IF(U25="","Não risco",IF((TODAY()-U25)<=7,"Risco","Não risco")) -> Não risco | AS25: =IF(SEARCH("integrar",P25)>0,"Sim","Não") -> #VALUE! | AT25: =IF(S25="",TODAY()-Q25,S25-Q25) -> 19 | AU25: =VLOOKUP(X25,'pontos focais'!C:D,2,0) -> DEOP Qualidade | AV25: =U25-Q25 -> -46269
A26: 1090 | B26: Visita Domo de Ferro | C26: Obra | D26: DCMD | E26: 46268 | F26: Dian Cleiton de Brito | G26: Em Andamento | H26: Em Andamento | K26: 0402600380 | L26: SUL | M26: Laguna Carapã | N26: Prefeitura | O26: Laguna Carapã | P26: Prefeito solicita a relocação em caráter emergencial, pois tem risco de perder recurso para construção de imoveis na área em questão. Obra 0402600380 Expectatica: 30:09:26 | Q26: 46269 | R26: Obra 0402600380 - Programação. | S26: 46280 | V26: 46294 | X26: Amanda Aparecida Teixeira dos Santos | Y26: Amanda Santos | Z26: Itamar - Prefeito | AA26: Dian Cleiton de Brito | AB26: Sim | AC26: Visita Domo de Ferro | AD26: 46280 | AE26: Amanda Aparecida Teixeira dos Santos | AF26: 46280 | AG26: Amanda Aparecida Teixeira dos Santos | AH26: 100 | AI26: 100 | AJ26: 100 | AN26: =VLOOKUP(M26,[1]municipios!$B:$D,3,0) -> PONTA PORA | AO26: =TODAY()-E26 -> 20 | AP26: =IF(AO26<=5,"0–5 dias",IF(AO26<=15,"6–15 dias",IF(AO26<=16,"16–30 dias",IF(AO26<=30,"30–50 dias",">50 dias")))) -> 30–50 dias | AQ26: =IF(U26="","Dentro",(IF(IF(W26="",TODAY(),W26)<=U26,"Dentro","Fora"))) -> Dentro | AR26: =IF(U26="","Não risco",IF((TODAY()-U26)<=7,"Risco","Não risco")) -> Não risco | AS26: =IF(SEARCH("integrar",P26)>0,"Sim","Não") -> #VALUE! | AT26: =IF(S26="",TODAY()-Q26,S26-Q26) -> 11 | AU26: =VLOOKUP(X26,'pontos focais'!C:D,2,0) -> DCMD Programação de Obra | AV26: =U26-Q26 -> -46269
A27: 1093 | B27: Visita Domo de Ferro | C27: Informação | D27: Central do Cliente | E27: 46266 | F27: Giovani Moura Sousa | G27: Finalizada | H27: Finalizada | L27: SUL | M27: Amambai | N27: Câmara | O27: Amambai | P27: Interruções de nergia no centro da cidade de Amabai | Q27: 46269 | R27: Para direcionamento de ação ao DEOP é necessário fornecer mais informações, tais como, número de controle interno, número da unidade consumidora, dentre outros. | S27: 46269 | T27: Para direcionamento de ação ao DEOP é necessário fornecer mais informações, tais como, número de controle interno, número da unidade consumidora, dentre outros. | W27: 46269 | X27: Wander Idalino Machado | Y27: Wander Machado | Z27: Vereadora Suzana | AA27: Giovani Moura Sousa | AB27: Sim | AC27: Visita Domo de Ferro | AD27: 46269 | AE27: Wander Idalino Machado | AF27: 46269 | AG27: Wander Idalino Machado | AH27: 25 | AI27: 25 | AJ27: 25 | AN27: =VLOOKUP(M27,[1]municipios!$B:$D,3,0) -> PONTA PORA | AO27: =TODAY()-E27 -> 22 | AP27: =IF(AO27<=5,"0–5 dias",IF(AO27<=15,"6–15 dias",IF(AO27<=16,"16–30 dias",IF(AO27<=30,"30–50 dias",">50 dias")))) -> 30–50 dias | AQ27: =IF(U27="","Dentro",(IF(IF(W27="",TODAY(),W27)<=U27,"Dentro","Fora"))) -> Dentro | AR27: =IF(U27="","Não risco",IF((TODAY()-U27)<=7,"Risco","Não risco")) -> Não risco | AS27: =IF(SEARCH("integrar",P27)>0,"Sim","Não") -> #VALUE! | AT27: =IF(S27="",TODAY()-Q27,S27-Q27) -> 0 | AU27: =VLOOKUP(X27,'pontos focais'!C:D,2,0) -> Central do Cliente | AV27: =U27-Q27 -> -46269
A28: 1095 | B28: Visita Domo de Ferro | C28: Informação | D28: Central do Cliente | E28: 46266 | F28: Giovani Moura Sousa | G28: Finalizada | H28: Finalizada | L28: SUL | M28: Amambai | N28: Câmara | O28: Amambai | P28: Interrupções de energia no centro da cidade de Amambai | Q28: 46269 | R28: Para direcionamento de ação ao DEOP é necessário fornecer mais informações, tais como, número de controle interno, número da unidade consumidora, dentre outros. | S28: 46269 | T28: Para direcionamento de ação ao DEOP é necessário fornecer mais informações, tais como, número de controle interno, número da unidade consumidora, dentre outros. | W28: 46269 | X28: Wander Idalino Machado | Y28: Wander Machado | Z28: Vereador darci José da Silva | AA28: Giovani Moura Sousa | AB28: Sim | AC28: Visita Domo de Ferro | AD28: 46269 | AE28: Wander Idalino Machado | AF28: 46269 | AG28: Wander Idalino Machado | AH28: 25 | AI28: 25 | AJ28: 25 | AN28: =VLOOKUP(M28,[1]municipios!$B:$D,3,0) -> PONTA PORA | AO28: =TODAY()-E28 -> 22 | AP28: =IF(AO28<=5,"0–5 dias",IF(AO28<=15,"6–15 dias",IF(AO28<=16,"16–30 dias",IF(AO28<=30,"30–50 dias",">50 dias")))) -> 30–50 dias | AQ28: =IF(U28="","Dentro",(IF(IF(W28="",TODAY(),W28)<=U28,"Dentro","Fora"))) -> Dentro | AR28: =IF(U28="","Não risco",IF((TODAY()-U28)<=7,"Risco","Não risco")) -> Não risco | AS28: =IF(SEARCH("integrar",P28)>0,"Sim","Não") -> #VALUE! | AT28: =IF(S28="",TODAY()-Q28,S28-Q28) -> 0 | AU28: =VLOOKUP(X28,'pontos focais'!C:D,2,0) -> Central do Cliente | AV28: =U28-Q28 -> -46269
A29: 1097 | B29: Visita Domo de Ferro | C29: Informação | D29: Central do Cliente | E29: 46269 | F29: Dian Cleiton de Brito | G29: Finalizada | H29: Finalizada | J29: 1.292.193.051-59 | L29: CENTRO | M29: Campo Grande | N29: Assembleia Legislativa | O29: Campo Grande | P29: Deputado relata que existe problema na injeção de creditos em sua unidade consumidora. Reclama do elevado consumo de sua residência. Expec: 04/09/26. Subsídios encaminhados via Teams aos cuidados do gestor de relacionamento Dian Cleiton em 04/09/2026. | Q29: 46269 | R29: Informação sobre faturamento GD - Unidade Consumidora 2406080. | S29: 46269 | T29: Controle Interno 2406080 - GD Troca de Medidor Para Aferição - Data 30/04/2025.OS 404908453 - Medidor Retirado W0002050271 Canal 03: 21178 Canal 103: 16581 Medidor Aprovado pelo INMETRO - Laudo 2859/2025 Em análise foi identificado que, na data de 29/05/2025 após ensaios realizados pelo INMETRO foi identificado que não havia inconsistências com o medidor W0002050271 retirado da unidade consumidora 2406080 através da ordem de serviço 404908453. Esclarecemos que, na ocasião o medidor W0002050271 apresentava as leituras (03 consumo medido 21178 e 103 energia injetada 16581), contabilizando 560 KWh de consumo residual e 143 KWh de energia ativa injetada residual. Após a substituição dos medidores as leituras foram coletadas mensalmente com visitas regulares realizadas por nossos leituristas e confirmação das grandezas faturáveis (consumo e injetado). Em consulta ao histórico de leitura e faturamento da unidade identificamos que, até a referência 05/2024 a unidade consumidora apresentava uma média de consumo inferior a média de energia injetada, dessa maneira, ao longo dos meses anteriores a energia injetada era superior ao consumo medido, logo, ocorria a compensação de todo consumo medido restando saldo excedente acumulado para compensação nos faturamentos subsequentes. Esclarecemos que, a partir da referência 11/2024 a unidade em questão passou a apresentar uma média de consumo superior ao injetado, no entanto, devido a existência de saldo acumulado de meses anteriores durante o processo de faturamento a compensação estava ocorrendo até o limite do custo de disponibilidade conforme dispõe a resolução vigente. Cumpre informar, que até a referência 07/2026 a unidade consumidora dispunha de 680 KWh em saldo acumulado de meses anteriores, portanto, a diferença entre o consumo medido e o injetado na respectiva referência foi compensado considerando o saldo informado resultando em uma diferença de 174 KWh, ocasionando na fatura de R$ 328,70. Para o faturamento da referência 08/2026, foi identificado que, na data de 18/08/2026 em visita realizada ao imóvel foram coletadas as leituras (03 consumo medido 13.562 e 103 energia injetada 11.436), contabilizando 1.405 KWh de consumo e 627 KWh de injetado. Logo, devido ao esgotamento do saldo excedente acumulado em meses anteriores, houve a compensação de toda a energia injetada no respectivo faturamento (627 KWh), restando uma diferença de 778 KWh (consumo medido), resultando na fatura emitida no valor de R$ 1.112,83. Diante dos dados de medição (leituras), informo que o consumo medido e o injetado na referência 08/2026 estão de acordo com os registros contabilizados pelo equipamento de medição instalado na unidade reclamada. Portanto, a fatura emitida no valor de R$ 1.112,83 está correta não havendo înconsistências com o respectivo faturamento. | W29: 46269 | X29: Wander Idalino Machado | Y29: Wander Machado | Z29: Geraldo Resende - Deputado Anne Jackeline - Secretária | AA29: Dian Cleiton de Brito | AB29: Sim | AC29: Visita Domo de Ferro | AD29: 46269 | AE29: Wander Idalino Machado | AF29: 46269 | AG29: Wander Idalino Machado | AH29: 100 | AI29: 100 | AJ29: 100 | AN29: =VLOOKUP(M29,[1]municipios!$B:$D,3,0) -> CAMPO GRANDE | AO29: =TODAY()-E29 -> 19 | AP29: =IF(AO29<=5,"0–5 dias",IF(AO29<=15,"6–15 dias",IF(AO29<=16,"16–30 dias",IF(AO29<=30,"30–50 dias",">50 dias")))) -> 30–50 dias | AQ29: =IF(U29="","Dentro",(IF(IF(W29="",TODAY(),W29)<=U29,"Dentro","Fora"))) -> Dentro | AR29: =IF(U29="","Não risco",IF((TODAY()-U29)<=7,"Risco","Não risco")) -> Não risco | AS29: =IF(SEARCH("integrar",P29)>0,"Sim","Não") -> #VALUE! | AT29: =IF(S29="",TODAY()-Q29,S29-Q29) -> 0 | AU29: =VLOOKUP(X29,'pontos focais'!C:D,2,0) -> Central do Cliente | AV29: =U29-Q29 -> -46269
A30: 1098 | B30: Visita Domo de Ferro | C30: Obra | D30: DCMD | E30: 46269 | F30: Dian Cleiton de Brito | G30: Finalizada | H30: Finalizada | K30: 0302600330 | L30: SUL | M30: Ivinhema | N30: Assembleia Legislativa | O30: Ivinhema | P30: DEPUTADO SOLICITA AGILIZAR OBRA DE MELHORIA PARA ATENDIMENTO A AUMENTO DE CARGA. EXPECTATIVA 05/10/26. Orçamento não foi aprovado pelo cliente, dessa maneira, no há possibilidade de agilizar atendimento da obra (agente institucional) orientado via Teams. | Q30: 46269 | R30: Obra 0302600330 - agilizar programação. | S30: 46280 | T30: ORÇAMENTO AINDA NAO APROVADO PELO CLIENTE | U30: 46300 | X30: Amanda Aparecida Teixeira dos Santos | Y30: Amanda Santos | Z30: Zé Teixeira - DEPUTADO Paulo Roberto - DPRE | AA30: Dian Cleiton de Brito | AB30: Sim | AC30: Visita Domo de Ferro | AD30: 46280 | AE30: Amanda Aparecida Teixeira dos Santos | AF30: 46280 | AG30: Amanda Aparecida Teixeira dos Santos | AH30: 100 | AI30: 100 | AJ30: 100 | AN30: =VLOOKUP(M30,[1]municipios!$B:$D,3,0) -> NOVA ANDRADINA | AO30: =TODAY()-E30 -> 19 | AP30: =IF(AO30<=5,"0–5 dias",IF(AO30<=15,"6–15 dias",IF(AO30<=16,"16–30 dias",IF(AO30<=30,"30–50 dias",">50 dias")))) -> 30–50 dias | AQ30: =IF(U30="","Dentro",(IF(IF(W30="",TODAY(),W30)<=U30,"Dentro","Fora"))) -> Dentro | AR30: =IF(U30="","Não risco",IF((TODAY()-U30)<=7,"Risco","Não risco")) -> Risco | AS30: =IF(SEARCH("integrar",P30)>0,"Sim","Não") -> #VALUE! | AT30: =IF(S30="",TODAY()-Q30,S30-Q30) -> 11 | AU30: =VLOOKUP(X30,'pontos focais'!C:D,2,0) -> DCMD Programação de Obra | AV30: =U30-Q30 -> 31
A31: 1105 | B31: Visita Domo de Ferro | C31: Obra | D31: DCMD | E31: 46161.042 | F31: Dian Cleiton de Brito | G31: Em Andamento | H31: Em Andamento | K31: 0302500469 | L31: SUL | M31: Bataguassu | N31: Diretoria | O31: Bataguassu | P31: Solicita realizar a ligação com urgência do loteamento | Q31: 46274 | R31: Obra 0302500469 - Favor incluir na programação. | S31: 46282 | V31: 46307 | X31: Amanda Aparecida Teixeira dos Santos | Y31: Amanda Santos | Z31: Paulo Roberto do Santos | AA31: Dian Cleiton de Brito | AB31: Sim | AC31: Visita Domo de Ferro | AD31: 46282 | AE31: Amanda Aparecida Teixeira dos Santos | AF31: 46282 | AG31: Amanda Aparecida Teixeira dos Santos | AH31: 100 | AI31: 100 | AJ31: 100 | AN31: =VLOOKUP(M31,[1]municipios!$B:$D,3,0) -> NOVA ANDRADINA | AO31: =TODAY()-E31 -> 126.95833 | AP31: =IF(AO31<=5,"0–5 dias",IF(AO31<=15,"6–15 dias",IF(AO31<=16,"16–30 dias",IF(AO31<=30,"30–50 dias",">50 dias")))) -> >50 dias | AQ31: =IF(U31="","Dentro",(IF(IF(W31="",TODAY(),W31)<=U31,"Dentro","Fora"))) -> Dentro | AR31: =IF(U31="","Não risco",IF((TODAY()-U31)<=7,"Risco","Não risco")) -> Não risco | AS31: =IF(SEARCH("integrar",P31)>0,"Sim","Não") -> #VALUE! | AT31: =IF(S31="",TODAY()-Q31,S31-Q31) -> 8 | AU31: =VLOOKUP(X31,'pontos focais'!C:D,2,0) -> DCMD Programação de Obra | AV31: =U31-Q31 -> -46274
A32: 1110 | B32: Visita Domo de Ferro | C32: Obra | D32: DCMD | E32: 46274 | F32: Dian Cleiton de Brito | G32: Em Andamento | H32: Não Iniciada | I32: HAMMES COMÉRCIO DE CEREAIS LTDA. ME | K32: 0202600853 | L32: SUL | M32: Rio Brilhante | N32: Assembleia Legislativa | O32: Rio Brilhante | P32: Solicita agilizar a realização da obra 0202600853 EXPECTATIVA: 20/09/26 | Q32: 46275 | R32: Obra 0202600853 favor incluir na programação. | U32: 46285 | X32: Amanda Aparecida Teixeira dos Santos | Z32: Zé Teixeira Paulo Roberto | AA32: Dian Cleiton de Brito | AB32: Sim | AC32: Visita Domo de Ferro | AD32: 46276 | AE32: Wander Idalino Machado | AF32: 46276 | AG32: Wander Idalino Machado | AH32: 100 | AI32: 100 | AJ32: 50 | AK32: Programação de Obras e Gestão de Materiais | AM32: DCMD - PROGRAMAÇÃO DE OBRA | AN32: =VLOOKUP(M32,[1]municipios!$B:$D,3,0) -> RIO BRILHANTE | AO32: =TODAY()-E32 -> 14 | AP32: =IF(AO32<=5,"0–5 dias",IF(AO32<=15,"6–15 dias",IF(AO32<=16,"16–30 dias",IF(AO32<=30,"30–50 dias",">50 dias")))) -> 6–15 dias | AQ32: =IF(U32="","Dentro",(IF(IF(W32="",TODAY(),W32)<=U32,"Dentro","Fora"))) -> Fora | AR32: =IF(U32="","Não risco",IF((TODAY()-U32)<=7,"Risco","Não risco")) -> Risco | AS32: =IF(SEARCH("integrar",P32)>0,"Sim","Não") -> #VALUE! | AT32: =IF(S32="",TODAY()-Q32,S32-Q32) -> 13 | AU32: =VLOOKUP(X32,'pontos focais'!C:D,2,0) -> DCMD Programação de Obra | AV32: =U32-Q32 -> 10
A33: 1119 | B33: Visita Domo de Ferro | C33: Obra | D33: DCMD | E33: 46280 | F33: Dian Cleiton de Brito | G33: Em Andamento | H33: Não Iniciada | I33: IRANI ENERHARD | K33: 0202600755 | L33: SUL | M33: Dourados | N33: Assembleia Legislativa | O33: Dourados | P33: Deputado Solicita agilizar obra de execução de instalação de ponto de entrega. Expectativa 05/10/2026; | Q33: 46279 | R33: Obra 0202600755 - Por favor incluir na programação. | U33: 46300 | X33: Amanda Aparecida Teixeira dos Santos | Z33: Zé Teixeira Paulo Roberto | AA33: Dian Cleiton de Brito | AB33: Sim | AC33: Visita Domo de Ferro | AD33: 46280 | AE33: Wander Idalino Machado | AF33: 46280 | AG33: Wander Idalino Machado | AH33: 100 | AI33: 100 | AJ33: 50 | AK33: Programação de Obras e Gestão de Materiais | AM33: DCMD - PROGRAMAÇÃO DE OBRA | AN33: =VLOOKUP(M33,[1]municipios!$B:$D,3,0) -> DOURADOS | AO33: =TODAY()-E33 -> 8 | AP33: =IF(AO33<=5,"0–5 dias",IF(AO33<=15,"6–15 dias",IF(AO33<=16,"16–30 dias",IF(AO33<=30,"30–50 dias",">50 dias")))) -> 6–15 dias | AQ33: =IF(U33="","Dentro",(IF(IF(W33="",TODAY(),W33)<=U33,"Dentro","Fora"))) -> Dentro | AR33: =IF(U33="","Não risco",IF((TODAY()-U33)<=7,"Risco","Não risco")) -> Risco | AS33: =IF(SEARCH("integrar",P33)>0,"Sim","Não") -> #VALUE! | AT33: =IF(S33="",TODAY()-Q33,S33-Q33) -> 9 | AU33: =VLOOKUP(X33,'pontos focais'!C:D,2,0) -> DCMD Programação de Obra | AV33: =U33-Q33 -> 21
A34: 1120 | B34: Visita Domo de Ferro | C34: Atendimento Comercial | D34: DESC | E34: 46281 | F34: Dian Cleiton de Brito | G34: Em Andamento | H34: Não Iniciada | I34: PONTE PRETA PARTICIPAÇÕES SOCIETÁRIAS LTDA | J34: 2952299 | L34: CENTRO | M34: Campo Grande | N34: Governo do Estado | O34: Campo Grande | P34: SOLICITA AGILIZAR OS 558638822, considerando que a regularização foi executada. Expec 16/09/26 | Q34: 46281 | R34: Por favor agilizar atendimento da OS 563985314 - Vistoria Para Padronização. | U34: 46281 | X34: Jorge Luis Martinelli | Z34: Jaime Verruck Paulo Roberto dos Santos | AA34: Dian Cleiton de Brito | AB34: Sim | AC34: Visita Domo de Ferro | AD34: 46281 | AE34: Wander Idalino Machado | AF34: 46281 | AG34: Wander Idalino Machado | AH34: 100 | AI34: 100 | AJ34: 50 | AK34: Ligação Nova GA | AM34: DECP - LIGAÇÃO GA | AN34: =VLOOKUP(M34,[1]municipios!$B:$D,3,0) -> CAMPO GRANDE | AO34: =TODAY()-E34 -> 7 | AP34: =IF(AO34<=5,"0–5 dias",IF(AO34<=15,"6–15 dias",IF(AO34<=16,"16–30 dias",IF(AO34<=30,"30–50 dias",">50 dias")))) -> 6–15 dias | AQ34: =IF(U34="","Dentro",(IF(IF(W34="",TODAY(),W34)<=U34,"Dentro","Fora"))) -> Fora | AR34: =IF(U34="","Não risco",IF((TODAY()-U34)<=7,"Risco","Não risco")) -> Risco | AS34: =IF(SEARCH("integrar",P34)>0,"Sim","Não") -> #VALUE! | AT34: =IF(S34="",TODAY()-Q34,S34-Q34) -> 7 | AU34: =VLOOKUP(X34,'pontos focais'!C:D,2,0) -> DECP - Ligação GA | AV34: =U34-Q34 -> 0
A35: 120 | B35: Visita Domo de Ferro | C35: Obra | D35: DCMD | E35: 46150 | F35: Dian Cleiton de Brito | G35: Finalizada | H35: Finalizada | K35: 0302500469 | L35: SUL | M35: Bataguassu | N35: Diretoria | O35: Bataguassu | P35: Solicita agilizar obra de ponto de entrega e loteamento - obra 0302500469 Expectativa - 10/06/26. PE 7175625 OBRAS ASSOCIADAS AO PE FINALIDAS. | Q35: 46237 | R35: Solicita agilizar obra de ponto de entrega e loteamento - obra 0302500469 Expectativa - 10/06/26. PE 7175625. Nova expectativa do cliente 31/07/2026. | S35: 46247 | U35: 46234 | X35: Amanda Aparecida Teixeira dos Santos | Y35: Gabriella Domingo | Z35: Paulo Roberto dos Santos | AA35: Dian Cleiton de Brito | AB35: Sim | AC35: Visita Domo de Ferro | AD35: 46268 | AE35: Moacir Costa Neto | AF35: 46247 | AG35: Gabriella Amorim Domingo | AH35: 100 | AI35: 100 | AJ35: 75 | AN35: =VLOOKUP(M35,[1]municipios!$B:$D,3,0) -> NOVA ANDRADINA | AO35: =TODAY()-E35 -> 138 | AP35: =IF(AO35<=5,"0–5 dias",IF(AO35<=15,"6–15 dias",IF(AO35<=16,"16–30 dias",IF(AO35<=30,"30–50 dias",">50 dias")))) -> >50 dias | AQ35: =IF(U35="","Dentro",(IF(IF(W35="",TODAY(),W35)<=U35,"Dentro","Fora"))) -> Fora | AR35: =IF(U35="","Não risco",IF((TODAY()-U35)<=7,"Risco","Não risco")) -> Não risco | AS35: =IF(SEARCH("integrar",P35)>0,"Sim","Não") -> #VALUE! | AT35: =IF(S35="",TODAY()-Q35,S35-Q35) -> 10 | AU35: =VLOOKUP(X35,'pontos focais'!C:D,2,0) -> DCMD Programação de Obra | AV35: =U35-Q35 -> -3
A36: 120 | B36: Visita Domo de Ferro | C36: Obra | D36: DESC | E36: 46150 | F36: Dian Cleiton de Brito | G36: Finalizada | H36: Finalizada | L36: SUL | M36: Bataguassu | N36: Diretoria | O36: Bataguassu | P36: Solicita agilizar obra de ponto de entrega e loteamento - obra 0302500469 Expectativa - 10/06/26. PE 7175625 OBRAS ASSOCIADAS AO PE FINALIDAS. | Q36: 46195 | R36: Dian, gentileza reavaliar a expectativa do cliente. Solicita agilizar obra de ponto de entrega e loteamento - obra 0302500469 Expectativa - 10/06/26. PE 7175625 | S36: 46259 | T36: Obras relacionadas ao PE concluídas. | W36: 46259 | X36: Dian Cleiton de Brito | Y36: Wander Machado | Z36: Paulo Roberto dos Santos | AA36: Dian Cleiton de Brito | AB36: Sim | AC36: Visita Domo de Ferro | AD36: 46268 | AE36: Moacir Costa Neto | AF36: 46259 | AG36: Wander Idalino Machado | AH36: 100 | AI36: 100 | AJ36: 100 | AN36: =VLOOKUP(M36,[1]municipios!$B:$D,3,0) -> NOVA ANDRADINA | AO36: =TODAY()-E36 -> 138 | AP36: =IF(AO36<=5,"0–5 dias",IF(AO36<=15,"6–15 dias",IF(AO36<=16,"16–30 dias",IF(AO36<=30,"30–50 dias",">50 dias")))) -> >50 dias | AQ36: =IF(U36="","Dentro",(IF(IF(W36="",TODAY(),W36)<=U36,"Dentro","Fora"))) -> Dentro | AR36: =IF(U36="","Não risco",IF((TODAY()-U36)<=7,"Risco","Não risco")) -> Não risco | AS36: =IF(SEARCH("integrar",P36)>0,"Sim","Não") -> #VALUE! | AT36: =IF(S36="",TODAY()-Q36,S36-Q36) -> 64 | AU36: =VLOOKUP(X36,'pontos focais'!C:D,2,0) -> Institucional | AV36: =U36-Q36 -> -46195
A37: 670 | B37: Visita Domo de Ferro | C37: Poda | D37: DCMD | E37: 46084 | F37: Danila Hertal Moreira Souza | G37: Em Andamento | H37: Finalizada | J37: 9000076 | L37: NORTE | M37: Corumbá | N37: Diretoria | O37: Corumbá | P37: Origem Externa: SANESUL Nome do Solicitante: RENATO MARCILIO DA SILVA Número Ofício: 6226/2025/PSEC/ALEMS Manifestação: Em 02/03/2026 - realizada reunião presencial na Energisa com os diretores da SANESUL para tratar da qualidade de fornecimento das unidades de Corumbá. Conforme documento anexo, cliente reclama de constantes oscilações no fornecimento de energia elétrica nas unidades de Corumbá. No Município não existem poços profundos, assim toda a produção de agua para o sistema ocorre através de captação superficial direto do rio Paraguai. UCs: 9000076 1717627 30723 1699438 1702111 1698960 1142916 Segue ofício em anexo. | Q37: 46191 | R37: Status atual: Em atuação campo (DEOP/DCMD). Origem Externa: SANESUL Nome do Solicitante: RENATO MARCILIO DA SILVA Número Ofício: 6226/2025/PSEC/ALEMS Manifestação: Em 02/03/2026 - realizada reunião presencial na Energisa com os diretores da SANESUL para tratar da qualidade de fornecimento das unidades de Corumbá. Conforme documento anexo, cliente reclama de constantes oscilações no fornecimento de energia elétrica nas unidades de Corumbá. No Município não existem poços profundos, assim toda a produção de agua para o sistema ocorre através de captação superficial direto do rio Paraguai. UCs: 9000076 1717627 30723 1699438 1702111 1698960 1142916 Segue ofício em anexo. | S37: 46269 | T37: Podas e limpeza de faixas concluidas dia 04/09/26 | U37: 46234 | W37: 46269 | X37: Evair Rogerio da Conceicao | Y37: Gabriella Domingo | AA37: Danila Hertal Moreira Souza | AB37: Sim | AC37: Visita Domo de Ferro | AD37: 46269 | AE37: Gabriella Amorim Domingo | AF37: 46269 | AG37: Gabriella Amorim Domingo | AH37: 100 | AI37: 100 | AJ37: 100 | AN37: =VLOOKUP(M37,[1]municipios!$B:$D,3,0) -> CORUMBA | AO37: =TODAY()-E37 -> 204 | AP37: =IF(AO37<=5,"0–5 dias",IF(AO37<=15,"6–15 dias",IF(AO37<=16,"16–30 dias",IF(AO37<=30,"30–50 dias",">50 dias")))) -> >50 dias | AQ37: =IF(U37="","Dentro",(IF(IF(W37="",TODAY(),W37)<=U37,"Dentro","Fora"))) -> Fora | AR37: =IF(U37="","Não risco",IF((TODAY()-U37)<=7,"Risco","Não risco")) -> Não risco | AS37: =IF(SEARCH("integrar",P37)>0,"Sim","Não") -> #VALUE! | AT37: =IF(S37="",TODAY()-Q37,S37-Q37) -> 78 | AU37: =VLOOKUP(X37,'pontos focais'!C:D,2,0) -> DCMD Manutenção | AV37: =U37-Q37 -> 43
A38: 670 | B38: Visita Domo de Ferro | C38: Qualidade | D38: DEOP | E38: 46084 | F38: Danila Hertal Moreira Souza | G38: Em Andamento | H38: Em Andamento | J38: 9000076 | L38: NORTE | M38: Corumbá | N38: Diretoria | O38: Corumbá | P38: Origem Externa: SANESUL Nome do Solicitante: RENATO MARCILIO DA SILVA Número Ofício: 6226/2025/PSEC/ALEMS Manifestação: Em 02/03/2026 - realizada reunião presencial na Energisa com os diretores da SANESUL para tratar da qualidade de fornecimento das unidades de Corumbá. Conforme documento anexo, cliente reclama de constantes oscilações no fornecimento de energia elétrica nas unidades de Corumbá. No Município não existem poços profundos, assim toda a produção de agua para o sistema ocorre através de captação superficial direto do rio Paraguai. UCs: 9000076 1717627 30723 1699438 1702111 1698960 1142916 Segue ofício em anexo. | Q38: 46233 | R38: Conforme pactuado na reunião de qualidade realizada em 23/07/2026, ficou como saída a instalação de 07 medidores para avaliação dos níveis de tensão das unidades reclamadas e refazer os estudos de religamentos. Conforme alinhado o DESC planilhou as unidades consumidoras por ordem de prioridade para as devidas atuações (planilha em anexo). | S38: 46269 | X38: Luan Henrique Soares Diniz Afonso | Y38: Gabriella Domingo | AA38: Danila Hertal Moreira Souza | AB38: Sim | AC38: Visita Domo de Ferro | AD38: 46269 | AE38: Gabriella Amorim Domingo | AF38: 46269 | AG38: Gabriella Amorim Domingo | AH38: 100 | AI38: 100 | AJ38: 100 | AN38: =VLOOKUP(M38,[1]municipios!$B:$D,3,0) -> CORUMBA | AO38: =TODAY()-E38 -> 204 | AP38: =IF(AO38<=5,"0–5 dias",IF(AO38<=15,"6–15 dias",IF(AO38<=16,"16–30 dias",IF(AO38<=30,"30–50 dias",">50 dias")))) -> >50 dias | AQ38: =IF(U38="","Dentro",(IF(IF(W38="",TODAY(),W38)<=U38,"Dentro","Fora"))) -> Dentro | AR38: =IF(U38="","Não risco",IF((TODAY()-U38)<=7,"Risco","Não risco")) -> Não risco | AS38: =IF(SEARCH("integrar",P38)>0,"Sim","Não") -> #VALUE! | AT38: =IF(S38="",TODAY()-Q38,S38-Q38) -> 36 | AU38: =VLOOKUP(X38,'pontos focais'!C:D,2,0) -> DEOP Qualidade | AV38: =U38-Q38 -> -46233
